Workbook

Sheet Suivis et pilotage
B3: Prestation | C3: Coût HT | D3: TVA (20%) | E3: Coût TTC | F3: Prestataire
F4: ECO-COMPENSATION | G4: SIMETHIS | H4: CERAG
A5: Pilotage et coordination | B5: Coordination de l'équipe projet et des entreprises travaux | C5: =F5+G5 -> 975 | D5: =C5*0.2 -> 195 | E5: =C5+D5 -> 1170 | F5: 975 | G5: 0 | H5: 0
B6: Interface avec les services de l'état pour le compte de la SAS BEOLETTO | C6: =F6+G6 -> 150 | D6: =C6*0.2 -> 30 | E6: =C6+D6 -> 180 | F6: 150 | G6: 0 | H6: 0
B7: Bilan annuel incluant un CR (fiche synthèse avec tableau de bord ) | C7: =F7+G7 -> 1300 | D7: =C7*0.2 -> 260 | E7: =C7+D7 -> 1560 | F7: 1300 | G7: 0 | H7: 0
B9: Sous-total pour 1 campagne | C9: =SUM(C5:C7) -> 2425 | D9: =SUM(D5:D7) -> 485 | E9: =SUM(E5:E7) -> 2910 | F9: =SUM(F5:F7) -> 2425 | G9: =SUM(G5:G7) -> 0 | H9: =SUM(H5:H7) -> 0
B11: Total pour les 11 campagnes | C11: =C9*11 -> 26675 | D11: =D9*11 -> 5335 | E11: =E9*11 -> 32010 | F11: =F9*11 -> 26675 | G11: =G9*11 -> 0 | H11: =H9*11 -> 0
B13: Prestation | C13: Coût HT | D13: TVA (20%) | E13: Coût TTC | F13: Prestataire
F14: ECO-COMPENSATION | G14: SIMETHIS | H14: CERAG
A15: Pilotage et coordination (hors période de suivi) | B15: Coordination de l'équipe projet et des entreprises travaux | C15: =F15+G15 -> 975 | D15: =C15*0.2 -> 195 | E15: =C15+D15 -> 1170 | F15: 975 | G15: 0 | H15: 0
B16: Interface avec les services de l'état pour le compte de la SAS BEOLETTO | C16: =F16+G16 -> 150 | D16: =C16*0.2 -> 30 | E16: =C16+D16 -> 180 | F16: 150 | G16: 0 | H16: 0
B18: Sous-total pour 1 campagne | C18: =SUM(C15:C16) -> 1125 | D18: =SUM(D15:D16) -> 225 | E18: =SUM(E15:E16) -> 1350 | F18: =SUM(F15:F16) -> 1125 | G18: =SUM(G15:G16) -> 0 | H18: =SUM(H15:H16) -> 0
B20: Total pour les 20 campagnes | C20: =C18*20 -> 22500 | D20: =D18*20 -> 4500 | E20: =E18*20 -> 27000 | F20: =F18*20 -> 22500 | G20: =G18*20 -> 0 | H20: =H18*20 -> 0
B23: Prestation | C23: Coût HT | D23: TVA (20%) | E23: Coût TTC | F23: Prestataire
F24: ECO-COMPENSATION | G24: SIMETHIS | H24: CERAG
A25: Encadrement écologique des opérations de génie ecogiques (Travaux uniques et d'entretien) | B25: Suivi écologique des travaux de génie écologique incluant un CR (13 demies-journées) | C25: =F25+G25 -> 975 | D25: =C25*0.2 -> 195 | E25: =C25+D25 -> 1170 | F25: 0 | G25: 975 | H25: 0
B27: Sous-total pour 1 campagne | C27: =SUM(C25:C25) -> 975 | D27: =SUM(D25:D25) -> 195 | E27: =SUM(E25:E25) -> 1170 | F27: =SUM(F25:F25) -> 0 | G27: =SUM(G25:G25) -> 975 | H27: =SUM(H25:H25) -> 0
B29: Total pour les 13 campagnes | C29: =C27*13 -> 12675 | D29: =D27*13 -> 2535 | E29: =E27*13 -> 15210 | F29: =F27*13 -> 0 | G29: =G27*13 -> 12675 | H29: =H27*13 -> 0
B31: Prestation | C31: Coût HT | D31: TVA (20%) | E31: Coût TTC | F31: Prestataire
F32: ECO-COMPENSATION | G32: SIMETHIS | H32: CERAG
A33: Mises à jour du plan par période de 5 ans | B33: Mise à jour du plan de gestion | C33: =SUM(F33:H33) -> 4100 | D33: =C33*0.2 -> 820 | E33: =SUM(C33:D33) -> 4920 | F33: 1300 | G33: 1300 | H33: 1500
B35: Total pour 1 campagne | C35: =SUM(C33:C33) -> 4100 | D35: =SUM(D33:D33) -> 820 | E35: =SUM(E33:E33) -> 4920 | F35: =SUM(F33:F33) -> 1300 | G35: =SUM(G33:G33) -> 1300 | H35: =SUM(H33:H33) -> 1500
B37: Prestation | C37: Coût HT | D37: TVA (20%) | E37: Coût TTC | F37: Prestataire
F38: ECO-COMPENSATION | G38: SIMETHIS | H38: CERAG
A39: Etat initial et suivis écologiques de l'espace de compensation | B39: Suivi amphibiens (1 passage nocturne) | C39: =SUM(F39:G39) -> 275 | D39: =C39*0.2 -> 55 | E39: =C39+D39 -> 330 | F39: 0 | G39: 275 | H39: 0
B40: Suivi entomofaune (2 passages) | C40: =SUM(F40:G40) -> 550 | D40: =C40*0.2 -> 110 | E40: =C40+D40 -> 660 | F40: 0 | G40: 550 | H40: 0
B41: Suivi floristique (1 passage habitats naturels et EEE) | C41: =SUM(F41:G41) -> 275 | D41: =C41*0.2 -> 55 | E41: =C41+D41 -> 330 | F41: 0 | G41: 275 | H41: 0
B42: Rédaction d'un rapport de suivi écologique de l'espace de compensation et du site projet incluant un bilan | C42: =SUM(F42:G42) -> 1950 | D42: =C42*0.2 -> 390 | E42: =C42+D42 -> 2340 | F42: 0 | G42: 1950 | H42: 0
B43: Rédaction de la fiche préparatoire à la saisie dans GéoMCE et transmission des données au format SINP après chaque campagne | C43: =SUM(F43:G43) -> 325 | D43: =C43*0.2 -> 65 | E43: =C43+D43 -> 390 | F43: 0 | G43: 325 | H43: 0
B45: Sous-total pour 1 campagne | C45: =SUM(C39:C43) -> 3375 | D45: =SUM(D39:D43) -> 675 | E45: =SUM(E39:E43) -> 4050 | F45: =SUM(F39:F43) -> 0 | G45: =SUM(G39:G43) -> 3375 | H45: =SUM(H39:H43) -> 0
B47: Total pour les 11 campagnes | C47: =C45*11 -> 37125 | D47: =D45*11 -> 7425 | E47: =E45*11 -> 44550 | F47: =F45*11 -> 0 | G47: =G45*11 -> 37125 | H47: =H45*11 -> 0
B49: Prestation | C49: Coût HT | D49: TVA (20%) | E49: Coût TTC | F49: Prestataire
F50: ECO-COMPENSATION | G50: SIMETHIS | H50: CERAG
A51: Etat initial et suivis piézométriques de la zone humide compensatoire | B51: Relevés des sondes à raison de 2 relevés par an sur les 5 premières années (N+1, N+2, N+3, N+4 et N+5) et sur les années N+10, N+15, N+20, N+25 et N+30 | C51: =SUM(F51:H51) -> 650 | D51: =C51*0.2 -> 130 | E51: =C51+D51 -> 780 | F51: 0 | G51: 0 | H51: 650
B53: Sous-total pour 1 campagne | C53: =SUM(C51) -> 650 | D53: =SUM(D51) -> 130 | E53: =SUM(E51) -> 780 | F53: =SUM(F51) -> 0 | G53: =SUM(G51) -> 0 | H53: =SUM(H51) -> 650
B55: Total pour les 11 campagnes | C55: =C53*11 -> 7150 | D55: =D53*11 -> 1430 | E55: =E53*11 -> 8580 | F55: =F53*11 -> 0 | G55: =G53*11 -> 0 | H55: =H53*11 -> 7150
B57: Prestation | C57: Coût HT | D57: TVA (20%) | E57: Coût TTC | F57: Prestataire
F58: ECO-COMPENSATION | G58: SIMETHIS | H58: CERAG
A59: Etat initial et suivis pédologiques de la zone humide compensatoire | B59: Campagnes de sondages pédologiques au droit de la zone humide compensatoire 1 campagne par an sur les 5 premières années (N+1, N+2, N+3, N+4 et N+5) puis sur les années N+10, N+15, N+20, N+25 et N+30 à la fin de l'hiver - début printemps | C59: =SUM(F59:H59) -> 800 | D59: =C59*0.2 -> 160 | E59: =C59+D59 -> 960 | F59: 0 | G59: 0 | H59: 800
B61: Sous-total pour 1 campagne | C61: =SUM(C59) -> 800 | D61: =SUM(D59) -> 160 | E61: =SUM(E59) -> 960 | F61: =SUM(F59) -> 0 | G61: =SUM(G59) -> 0 | H61: =SUM(H59) -> 800
...

Sheet Planning
E1: Etat de référence | F1: N | G1: N+1 | H1: N+2 | I1: N+3 | J1: N+4 | K1: N+5 | L1: N+6 | M1: N+7 | N1: N+8 | O1: N+9 | P1: N+10 | Q1: N+11 | R1: N+12 | S1: N+13 | T1: N+14 | U1: N+15 | V1: N+16 | W1: N+17 | X1: N+18 | Y1: N+19 | Z1: N+20 | AA1: N+21 | AB1: N+22 | AC1: N+23 | AD1: N+24 | AE1: N+25 | AF1: N+26 | AG1: N+27 | AH1: N+28 | AI1: N+29
B2: PILOTAGE ET SUIVIS ECOLOGIQUES | D2: Code mesure | E2: 2023 | F2: 2024 | G2: 2025 | H2: 2026 | I2: 2027 | J2: 2028 | K2: 2029 | L2: 2030 | M2: 2031 | N2: 2032 | O2: 2033 | P2: 2034 | Q2: 2035 | R2: 2036 | S2: 2037 | T2: 2038 | U2: 2039 | V2: 2040 | W2: 2041 | X2: 2042 | Y2: 2043 | Z2: 2044 | AA2: 2045 | AB2: 2046 | AC2: 2047 | AD2: 2048 | AE2: 2049 | AF2: 2050 | AG2: 2051 | AH2: 2052 | AI2: 2053
B3: Pilotage et coordination | C3: Coordination de l'équipe projet et des entreprises travaux | D3: MG 1 | E3: X | F3: X | G3: X | H3: X | I3: X | J3: X | K3: X | L3: X | M3: X | N3: X | O3: X | P3: X | Q3: X | R3: X | S3: X | T3: X | U3: X | V3: X | W3: X | X3: X | Y3: X | Z3: X | AA3: X | AB3: X | AC3: X | AD3: X | AE3: X | AF3: X | AG3: X | AH3: X | AI3: X
C4: Interface avec les services de l'état pour le compte de la SAS BEOLETTO | E4: X | F4: X | G4: X | H4: X | I4: X | J4: X | K4: X | L4: X | M4: X | N4: X | O4: X | P4: X | Q4: X | R4: X | S4: X | T4: X | U4: X | V4: X | W4: X | X4: X | Y4: X | Z4: X | AA4: X | AB4: X | AC4: X | AD4: X | AE4: X | AF4: X | AG4: X | AH4: X | AI4: X
C5: Résumé non technique en fin de chaque campagne de suivi | E5: X | F5: X | G5: X | H5: X | I5: X | J5: X | K5: X | L5: X | M5: X | N5: X | O5: X | P5: X | Q5: X | R5: X | S5: X | T5: X | U5: X | V5: X | W5: X | X5: X | Y5: X | Z5: X | AA5: X | AB5: X | AC5: X | AD5: X | AE5: X | AF5: X | AG5: X | AH5: X | AI5: X
B6: Mises à jour du plan de gestion tous les 5 ans | C6: Mises à jour du plan de gestion | D6: MG 2 | E6: X | J6: X | O6: X | T6: X | Y6: X | AD6: X
B7: Encadrement écologique | C7: Encadrement écologique des opérations de génie éclogiques (travaux uniques et d'entretien) incluant un CR | D7: MG 1 | E7: 3 demies-journées | F7: 1 demie-journée | I7: 1 demie-journée | L7: 1 demie-journée | O7: 1 demie-journée | R7: 1 demie-journée | U7: 1 demie-journée | X7: 1 demie-journée | AA7: 1 demie-journée | AD7: 1 demie-journée | AG7: 1 demie-journée
B8: Etat initial et suivis écologiques de l'espace de compensation | C8: Suivi amphibiens (1 passage nocturne) | D8: SE 4 | E8: X | F8: X | G8: X | H8: X | I8: X | J8: X | O8: X | T8: X | Y8: X | AD8: X | AI8: X
C9: Suivi entomofaune (3 passages) | E9: X | F9: X | G9: X | H9: X | I9: X | J9: X | O9: X | T9: X | Y9: X | AD9: X | AI9: X
C10: Suivi floristique (1 passage habitats naturels et EEE) | E10: X | F10: X | G10: X | H10: X | I10: X | J10: X | K10: ² | O10: X | T10: X | Y10: X | AD10: X | AI10: X
C11: Rédaction d'un rapport de suivi écologique de l'espace de compensation et du site projet incluant un bilan | E11: X | F11: X | G11: X | H11: X | I11: X | J11: X | O11: X | T11: X | Y11: X | AD11: X | AI11: X
C12: Rédaction de la fiche préparatoire à la saisie dans GéoMCE et transmission des données au format SINP après chaque campagne | E12: X | F12: X | G12: X | H12: X | I12: X | J12: X | O12: X | T12: X | Y12: X | AD12: X | AI12: X
B13: Etat initial et suivis piézomériques et pédologiques de la zone humide compensatoire | C13: Relevés des sondes à raison de 2 relevés par an sur les 5 premières années puis tous les 5 ans | D13: SE 1 | E13: 2 relevés | F13: 2 relevés | G13: 2 relevés | H13: 2 relevés | I13: 2 relevés | J13: 2 relevés | O13: 2 relevés | T13: 2 relevés | Y13: 2 relevés | AD13: 2 relevés | AI13: 2 relevés
C14: Sondages pédologiques à la tarière à main | D14: SE 2 | E14: X | F14: X | G14: X | H14: X | I14: X | J14: X | O14: X | T14: X | Y14: X | AD14: X | AI14: X
C15: Rédaction d'un rapport de suivi | D15: SE 1 et SE2 | E15: X | F15: X | G15: X | H15: X | I15: X | J15: X | O15: X | T15: X | Y15: X | AD15: X | AI15: X
B16: Etat initial et suivis hydromorphologique du fossé | C16: Suivi hydromorphologique et rédaction d'un rapport de suivi | D16: SE 3 | E16: X | J16: X | O16: X | T16: X | Y16: X | AD16: X | AI16: X
B17: Rédaction d'un bilan de fin des mesures compensatoires | C17: Rédaction d'un bilan de fin des mesures compensatoires | D17: MG 2 | AI17: X
E19: Etat de référence | F19: N | G19: N+1 | H19: N+2 | I19: N+3 | J19: N+4 | K19: N+5 | L19: N+6 | M19: N+7 | N19: N+8 | O19: N+9 | P19: N+10 | Q19: N+11 | R19: N+12 | S19: N+13 | T19: N+14 | U19: N+15 | V19: N+16 | W19: N+17 | X19: N+18 | Y19: N+19 | Z19: N+20 | AA19: N+21 | AB19: N+22 | AC19: N+23 | AD19: N+24 | AE19: N+25 | AF19: N+26 | AG19: N+27 | AH19: N+28 | AI19: N+29
B20: TRAVAUX DE GENIE ECOLOGIQUE | D20: Code mesure | E20: 2023 | F20: 2024 | G20: 2025 | H20: 2026 | I20: 2027 | J20: 2028 | K20: 2029 | L20: 2030 | M20: 2031 | N20: 2032 | O20: 2033 | P20: 2034 | Q20: 2035 | R20: 2036 | S20: 2037 | T20: 2038 | U20: 2039 | V20: 2040 | W20: 2041 | X20: 2042 | Y20: 2043 | Z20: 2044 | AA20: 2045 | AB20: 2046 | AC20: 2047 | AD20: 2048 | AE20: 2049 | AF20: 2050 | AG20: 2051 | AH20: 2052 | AI20: 2053
B21: Travaux de génie écologique (travaux uniques) | C21: Pose de 2 piézomètres incluant la maintance tous les 5 ans* | D21: SE 1 | E21: X | J21: X | O21: X | T21: X | Y21: X | AD21: X | AI21: X
C22: Equipements des piézomètres avec des sondes et remplacement au bout de 10 ans | D22: SE 1 | E22: X | O22: X | Y22: X
C23: Création de 2 dépressions humides par étrépage (30 cm) - environ 2 x 200 m² | D23: TU 1 | E23: X
C24: Travaux de décapage (50 cm) sur les deux dépressions | D24: TU 1 | E24: X
C25: Travaux de décapage (50 cm) + imperméablisation argile sur les deux dépressions | D25: TU 1 | E25: X
C26: Création d'un seuil en rondins de bois (option) | D26: TU 2 | E26: Si nécéssaire à l'issue des premiers suivis
C27: Suppression et évacuation des ligneux | D27: TU 3 | E27: X
B28: Travaux de génie écologique (travaux d'entretien) | C28: Entretien des landes humides | D28: TE 1 | F28: X | I28: X | L28: X | O28: X | R28: X | U28: X | X28: X | AA28: X | AD28: X | AG28: X
E30: Etat de référence | F30: N | G30: N+1 | H30: N+2 | I30: N+3 | J30: N+4 | K30: N+5 | L30: N+6 | M30: N+7 | N30: N+8 | O30: N+9 | P30: N+10 | Q30: N+11 | R30: N+12 | S30: N+13 | T30: N+14 | U30: N+15 | V30: N+16 | W30: N+17 | X30: N+18 | Y30: N+19 | Z30: N+20 | AA30: N+21 | AB30: N+22 | AC30: N+23 | AD30: N+24 | AE30: N+25 | AF30: N+26 | AG30: N+27 | AH30: N+28 | AI30: N+29
B31: PILOTAGE ET SUIVIS ECOLOGIQUES | D31: Code mesure | E31: 2023 | F31: 2024 | G31: 2025 | H31: 2026 | I31: 2027 | J31: 2028 | K31: 2029 | L31: 2030 | M31: 2031 | N31: 2032 | O31: 2033 | P31: 2034 | Q31: 2035 | R31: 2036 | S31: 2037 | T31: 2038 | U31: 2039 | V31: 2040 | W31: 2041 | X31: 2042 | Y31: 2043 | Z31: 2044 | AA31: 2045 | AB31: 2046 | AC31: 2047 | AD31: 2048 | AE31: 2049 | AF31: 2050 | AG31: 2051 | AH31: 2052 | AI31: 2053
B32: Pilotage et coordination | C32: Coordination de l'équipe projet et des entreprises travaux | D32: MG 1 | E32: 2425 | F32: 2425 | G32: ='Suivis et pilotage'!C9 -> 2425 | H32: 2425 | I32: 2425 | J32: 2425 | K32: 1125 | L32: 1125 | M32: 1125 | N32: 1125 | O32: 2425 | P32: 1125 | Q32: 1125 | R32: 1125 | S32: 1125 | T32: 2425 | U32: 1125 | V32: 1125 | W32: 1125 | X32: 1125 | Y32: 2425 | Z32: 1125 | AA32: 1125 | AB32: 1125 | AC32: 1125 | AD32: 2425 | AE32: 1125 | AF32: 1125 | AG32: 1125 | AH32: 1125 | AI32: 2425 | AJ32: =SUM(E32:AI34) -> 49175
C33: Interface avec les services de l'état pour le compte de la SAS BEOLETTO
C34: Résumé non technique en fin de chaque campagne de suivi
B35: Mises à jour du plan de gestion tous les 5 ans | C35: Mises à jour du plan de gestion | D35: MG 2 | E35: ='Suivis et pilotage'!C35 -> 4100 | J35: Si nécéssaire | O35: Si nécéssaire | T35: Si nécéssaire | Y35: Si nécéssaire | AD35: Si nécéssaire | AJ35: =SUM(E35:AI35) -> 4100
B36: Encadrement écologique | C36: Encadrement écologique des opérations de génie éclogiques (travaux uniques et d'entretien) incluant un CR | D36: MG 1 | E36: 2925 | F36: 975 | I36: 975 | L36: 975 | O36: 975 | R36: 975 | U36: 975 | X36: 975 | AA36: 975 | AD36: 975 | AG36: 975 | AJ36: =SUM(E36:AI36) -> 12675
B37: Etat initial et suivis écologiques de l'espace de compensation | C37: Suivi amphibiens (1 passage nocturne) | D37: SE 4 | E37: 3375 | F37: 3375 | G37: 3375 | H37: 3375 | I37: 3375 | J37: 3375 | O37: 3375 | T37: 3375 | Y37: 3375 | AD37: 3375 | AI37: 3375 | AJ37: =SUM(E37:AI41) -> 37125
C38: Suivi entomofaune (3 passages)
C39: Suivi floristique (1 passage habitats naturels et EEE) | K39: ²
C40: Rédaction d'un rapport de suivi écologique de l'espace de compensation incluant un bilan
C41: Rédaction de la fiche préparatoire à la saisie dans GéoMCE et transmission des données au format SINP après chaque campagne
B42: Etat initial et suivis piézométriques, pédologiques et hydromorpholohiques de la zone humide compensatoire | C42: Relevés des sondes à raison de 2 relevés par an sur les 5 premières années puis tous les 5 ans | D42: SE 1 | E42: 2450 | F42: 2450 | G42: 2450 | H42: 2450 | I42: 2450 | J42: 2450 | O42: 2450 | T42: 2450 | Y42: 2450 | AD42: 2450 | AI42: 2450 | AJ42: =SUM(E42:AI45) -> 26950
...

Sheet DECOMPTE 2023
A3: 33689 - DECOMPTE GENERAL ANNEE 2023
A5: STRUCTURE | B5: PRESTATION | C5: MONTANT DU MARCHE HT | D5: DEJA FACTURE | E5: DONT PREMIER ACOMPTE HT | F5: DONT DEUXIEME ACOMPTE HT | G5: DONT TROISIEME ACOMPTE HT | H5: QUATRIEME ACOMPTE HT | I5: COMMENTAIRES
A6: ECO-COMPENSATION | B6: Pilotage et coordination | C6: =Planning!E32 -> 2425 | D6: =C6*0.3 -> 727.5 | E6: 727.5 | F6: 0 | G6: 0 | H6: =C6-E6 -> 1697.5 | I6: -
B7: Mise à jour du plan de gestion | C7: 1300 | D7: =C7*0.3 -> 390 | E7: 390 | F7: 0 | G7: 0 | H7: =C7-E7 -> 910 | I7: -
A8: ECO-COMPENSATION | C8: =SUM(C6:C7) -> 3725 | D8: =C8*0.3 -> 1117.5 | E8: 1117.5 | F8: =SUM(F6:F7) -> 0 | G8: =SUM(G6:G7) -> 0 | H8: =SUM(H6:H7) -> 2607.5 | I8: -
A9: SIMETHIS (SOUS-TRAITANT) | B9: Mise à jour du plan de gestion | C9: 1300 | D9: =C9*0.3 -> 390 | E9: 390 | F9: 0 | G9: 0 | H9: =-E9 -> -390 | I9: Prestation non réalisée (-1 300,00 €)
B10: Encadrement écologique | C10: =Planning!E36 -> 2925 | D10: =C10*0.3 -> 877.5 | E10: 877.5 | F10: 0 | G10: 0 | H10: =C10-D10 -> 2047.5 | I10: -
B11: Etat initial et suivis écologiques de l'espace de compensation | C11: =Planning!E37 -> 3375 | D11: =C11*0.3 -> 1012.5 | E11: 1012.5 | F11: 0 | G11: 0 | H11: =C11-E11 -> 2362.5 | I11: -
A12: SIMETHIS (SOUS-TRAITANT) | C12: =SUM(C9:C11) -> 7600 | D12: =C12*0.3 -> 2280 | E12: 2280 | F12: 0 | G12: 0 | H12: =SUM(H9:H11) -> 4020 | I12: -
A13: CERAG (SOUS-TRAITANT) | B13: Mise à jour du plan de gestion | C13: 1500 | D13: =C13*0.3 -> 450 | E13: 450 | F13: 0 | G13: 0 | H13: -450 | I13: Prestation non réalisée (-1 500,00 €)
B14: Etat initial et suivis piézométriques, pédologiques et hydromorpholohiques de la zone humide compensatoire | C14: =Planning!E42 -> 2450 | D14: =C14*0.3 -> 735 | E14: 735 | F14: 0 | G14: 0 | H14: =C14-E14 -> 1715 | I14: -
B15: Pose et équipement du piézomètre | C15: 3400 | D15: =C15*0.3 -> 1020 | E15: 1020 | F15: 0 | G15: 0 | H15: =C15-D15 -> 2380 | I15: -
A16: CERAG (SOUS-TRAITANT) | C16: =SUM(C13:C15) -> 7350 | D16: =C16*0.3 -> 2205 | E16: 2205 | F16: 0 | G16: 0 | H16: =SUM(H13:H15) -> 3645 | I16: -
A17: FACTURATION ECO-COMPENSATION | C17: =C8+C12+C16 -> 18675 | D17: =SUM(D8+D12+D16) -> 5602.5 | E17: =E8+E12+E16 -> 5602.5 | F17: =F8+F12+F16 -> 0 | G17: 0 | H17: =SUM(H16+H12+H8) -> 10272.5
A19: EGAN Aquitaine (CO-TRAITANT) | B19: Installation et repli de chantier inlaunt la mise en place d'un grillage à mouton | C19: 3200 | D19: =E19+F19 -> 3200 | E19: 1600 | F19: =C19*0.5 -> 1600 | G19: 0 | H19: 0 | I19: 0
B20: Mise en place d'une clôture en grillage à mouton avec piquets bois - 200 ml | C20: 6000 | D20: =E20+F20 -> 6000 | E20: 6000 | F20: 0 | G20: 0 | H20: 0 | I20: 0
B21: Création de 2 dépressions humides par étrépage (50 cm) - environ 2 x 200 m² | C21: 5500 | D21: =E21+F21 -> 5500 | E21: 1650 | F21: =C21*0.7 -> 3850 | G21: 0 | H21: 0 | I21: 0
B22: Création d'un seuil en rondins de bois | C22: 1775 | D22: 0 | E22: 0 | F22: 0 | G22: 0 | H22: 0 | I22: Prestation non réalisée (-1 775,00 €)
B23: Suppression et évacuation des ligneux | C23: 4200 | D23: =E23+F23+G23 -> 4200 | E23: 0 | F23: =C23*0.3 -> 1260 | G23: =C23-F23 -> 2940 | H23: 0 | I23: 0
B24: Entretien des landes humides | C24: 1575 | D24: =E24+F24+G24 -> 1575 | E24: 0 | F24: =C24*0.3 -> 472.5 | G24: =C24-F24 -> 1102.5 | H24: 0 | I24: 0
A25: FACTURATION EGAN Aquitaine | C25: =SUM(C19:C24) -> 22250 | D25: =SUM(D19:D24)-D22 -> 20475 | E25: =SUM(E19:E24)-E22 -> 9250 | F25: =SUM(F19:F24)-F22 -> 7182.5 | G25: =SUM(G19:G24)-G22 -> 4042.5 | H25: 0 | I25: 0
A27: TOTAL ANNEE 2023 | C27: MONTANT DU MARCHE HT | E27: TOTAL DÉJÀ FACTURE HT | F27: TOTAL DÉJÀ FACTURE HT | G27: TOTAL DÉJÀ FACTURE HT | H27: TOTAL ACOMPTE A PAYER HT | I27: RESTANT A FACTURER TTC
A28: PREVISONNEL 2023 | C28: =C25+C17 -> 40925
A29: FIN DE MISSION 2023 | C29: =C25+C17-C9-C13-C22 -> 36350 | E29: =E17+E25 -> 14852.5 | F29: =F25 -> 7182.5 | G29: =G25 -> 4042.5 | H29: 10272.5 | I29: =(C29*1.2)-(E29*1.2)-(F29*1.2)-(G29*1.2)-(H29*1.2) -> 0
A31: Eco-Compensation : PREVISONNEL 2023 | C31: =C17 -> 18675
A32: Eco-Compensation : FIN DE MISSION 2023 | C32: =C17-C9-C13 -> 15875
A33: Eco-Compensation : différence | C33: =C31-C32 -> 2800

Sheet DECOMPTE 2024
A3: 33689 - DECOMPTE GENERAL ANNEE 2024
A5: STRUCTURE | B5: PRESTATION | C5: MONTANT DU MARCHE HT | D5: DEJA FACTURE | E5: PREMIER ACOMPTE HT | F5: DEUXIEME ACOMPTE HT | G5: COMMENTAIRES
A6: ECO-COMPENSATION | B6: Pilotage et coordination | C6: =Planning!E32 -> 2425 | D6: 0 | E6: =C6*0.3 -> 727.5 | F6: =C6*0.7 -> 1697.5 | G6: -
A7: ECO-COMPENSATION | B7: Encadrement écologique | C7: 975 | D7: 0 | E7: =C7*0.3 -> 292.5 | F7: =-E7 -> -292.5 | G7: non réalisée
A8: ECO-COMPENSATION | C8: =SUM(C6:C7) -> 3400 | D8: 0 | E8: =E6+E7 -> 1020 | F8: =SUM(F6:F7) -> 1405 | G8: -
A9: SIMETHIS (SOUS-TRAITANT) | B9: Etat initial et suivis écologiques de l'espace de compensation | C9: =Planning!E37 -> 3375 | D9: 0 | E9: =C9*0.3 -> 1012.5 | F9: =C9*0.7 -> 2362.5 | G9: -
A10: SIMETHIS (SOUS-TRAITANT) | C10: =SUM(C9:C9) -> 3375 | D10: 0 | E10: =E9 -> 1012.5 | F10: =SUM(F9) -> 2362.5 | G10: -
A11: CERAG (SOUS-TRAITANT) | B11: Etat initial et suivis piézométriques, pédologiques et hydromorpholohiques de la zone humide compensatoire | C11: =Planning!E42 -> 2450 | D11: 0 | E11: =C11*0.3 -> 735 | F11: =C11*0.7 -> 1715 | G11: -
A12: CERAG (SOUS-TRAITANT) | C12: =SUM(C11:C11) -> 2450 | D12: 0 | E12: =E11 -> 735 | F12: =SUM(F11) -> 1715 | G12: -
A13: FACTURATION ECO-COMPENSATION | C13: =C8+C10+C12 -> 9225 | D13: =SUM(D8+D10+D12) -> 0 | E13: =E8+E10+E12 -> 2767.5 | F13: =SUM(F8+F10+F12) -> 5482.5 | G13: -
A15: EGAN Aquitaine (CO-TRAITANT) | B15: - | C15: 0 | D15: 0 | E15: 0 | F15: 0 | G15: Absence de travaux en 2024
A16: FACTURATION EGAN Aquitaine | C16: =SUM(C15:C15) -> 0 | D16: 0 | E16: 0 | F16: 0 | G16: 0
A18: TOTAL ANNEE 2024 | C18: MONTANT DU MARCHE HT | E18: TOTAL DÉJÀ FACTURE HT | F18: TOTAL FACTURE HT | G18: RESTANT A FACTURER TTC
A19: PREVISONNEL 2024 | C19: =C16+C13 -> 9225
A20: FIN DE MISSION 2024 | C20: =C19 -> 9225 | E20: =E13+E16 -> 2767.5 | F20: =F13 -> 5482.5 | G20: =(C20-E20-F20)*1.2 -> 1170

Sheet DECOMPTE 2025
A11: 33689 - DECOMPTE GENERAL ANNEE 2025
A13: STRUCTURE | B13: PRESTATION | C13: MONTANT DU MARCHE HT | D13: DEJA FACTURE | E13: PREMIER ACOMPTE HT | F13: DEUXIEME ACOMPTE HT | G13: COMMENTAIRES
A14: ECO-COMPENSATION | B14: Pilotage et coordination | C14: =Planning!E32 -> 2425 | D14: 0 | E14: =C14*0.3 -> 727.5 | F14: =C14*0.7 -> 1697.5 | G14: -
A15: ECO-COMPENSATION | C15: =SUM(C14:C14) -> 2425 | D15: 0 | E15: =SUM(E14) -> 727.5 | F15: =C15*0.7 -> 1697.5 | G15: -
A16: SIMETHIS (SOUS-TRAITANT) | B16: Etat initial et suivis écologiques de l'espace de compensation | C16: =Planning!E37 -> 3375 | D16: 0 | E16: =C16*0.3 -> 1012.5 | F16: =C16*0.7 -> 2362.5 | G16: -
A17: SIMETHIS (SOUS-TRAITANT) | C17: =SUM(C16:C16) -> 3375 | D17: 0 | E17: =E16 -> 1012.5 | F17: =C17*0.7 -> 2362.5 | G17: -
A18: CERAG (SOUS-TRAITANT) | B18: Etat initial et suivis piézométriques, pédologiques et hydromorpholohiques de la zone humide compensatoire | C18: =Planning!E42 -> 2450 | D18: 0 | E18: =C18*0.3 -> 735 | F18: =C18*0.7 -> 1715 | G18: -
A19: CERAG (SOUS-TRAITANT) | C19: =SUM(C18:C18) -> 2450 | D19: 0 | E19: =E18 -> 735 | F19: =C19*0.7 -> 1715 | G19: -
A20: FACTURATION ECO-COMPENSATION | C20: =C15+C17+C19 -> 8250 | D20: =SUM(D15+D17+D19) -> 0 | E20: =E15+E17+E19 -> 2475 | F20: =F15+F17+F19 -> 5775 | G20: -
A22: EGAN Aquitaine (CO-TRAITANT) | B22: - | C22: 0 | D22: 0 | E22: 0 | F22: 0 | G22: Absence de travaux en 2025
A23: FACTURATION EGAN Aquitaine | C23: =SUM(C22:C22) -> 0 | D23: 0 | E23: 0 | F23: 0 | G23: 0
A25: TOTAL ANNEE 2025 | C25: MONTANT DU MARCHE HT | E25: TOTAL DÉJÀ FACTURE HT | F25: FACTURE HT | G25: RESTANT A FACTURER TTC
A26: PREVISONNEL 2025 | C26: =C23+C20 -> 8250
A27: FIN DE MISSION 2025 | C27: =C26 -> 8250 | E27: =E20+E23 -> 2475 | F27: =F20 -> 5775 | G27: =(C27-E27-F27)*1.2 -> 0

Sheet DECOMPTE 2026
A11: 33689 - DECOMPTE GENERAL ANNEE 2026
A13: STRUCTURE | B13: PRESTATION | C13: MONTANT DU MARCHE HT | D13: DEJA FACTURE | E13: PREMIER ACOMPTE HT | F13: COMMENTAIRES
A14: ECO-COMPENSATION | B14: Pilotage et coordination | C14: =Planning!E32 -> 2425 | D14: 0 | E14: =C14*0.3 -> 727.5 | F14: -
A15: ECO-COMPENSATION | C15: =SUM(C14:C14) -> 2425 | D15: 0 | E15: =SUM(E14) -> 727.5 | F15: -
A16: SIMETHIS (SOUS-TRAITANT) | B16: Etat initial et suivis écologiques de l'espace de compensation | C16: =Planning!E37 -> 3375 | D16: 0 | E16: =C16*0.3 -> 1012.5 | F16: -
A17: SIMETHIS (SOUS-TRAITANT) | C17: =SUM(C16:C16) -> 3375 | D17: 0 | E17: =E16 -> 1012.5 | F17: -
A18: CERAG (SOUS-TRAITANT) | B18: Etat initial et suivis piézométriques, pédologiques et hydromorpholohiques de la zone humide compensatoire | C18: =Planning!E42 -> 2450 | D18: 0 | E18: =C18*0.3 -> 735 | F18: -
A19: CERAG (SOUS-TRAITANT) | C19: =SUM(C18:C18) -> 2450 | D19: 0 | E19: =E18 -> 735 | F19: -
A20: FACTURATION ECO-COMPENSATION | C20: =C15+C17+C19 -> 8250 | D20: =SUM(D15+D17+D19) -> 0 | E20: =E15+E17+E19 -> 2475 | F20: -
A22: EGAN Aquitaine (CO-TRAITANT) | B22: - | C22: 0 | D22: 0 | E22: 0 | F22: Absence de travaux en 2025
A23: FACTURATION EGAN Aquitaine | C23: =SUM(C22:C22) -> 0 | D23: 0 | E23: 0 | F23: 0
A25: TOTAL ANNEE 2026 | C25: MONTANT DU MARCHE HT | E25: FACTURE HT | F25: RESTANT A FACTURER TTC
A26: PREVISONNEL 2026 | C26: =C23+C20 -> 8250
A27: FIN DE MISSION 2026 | C27: =C26 -> 8250 | E27: =E20+E23 -> 2475 | F27: =(C27-E27)*1.2 -> 6930

Sheet PGZHC
D2: Etat de référence | E2: N | F2: N+1 | G2: N+2 | H2: N+3 | I2: N+4 | J2: N+5 | K2: N+6 | L2: N+7 | M2: N+8 | N2: N+9
A3: TRAVAUX DE GENIE ECOLOGIQUE | C3: Code mesure | D3: 2023 | E3: 2024 | F3: 2025 | G3: 2026 | H3: 2027 | I3: 2028 | J3: 2029 | K3: 2030 | L3: 2031 | M3: 2032 | N3: 2033
A4: Travaux de génie écologique (travaux uniques) | B4: Pose de 1 piézomètres incluant la maintance tous les 5 ans et le remplacement au bout de 15 ans | C4: SE 1 | D4: Réalisé | I4: Projeté | N4: Projeté
B5: Equipements des piézomètres avec des sondes et remplacement au bout de 10 ans | C5: SE 1 | D5: Réalisé | N5: Projeté
B6: Installation et repli de chantier inlaunt la mise en place d'un grillage à mouton | C6: - | D6: Réalisé
B7: Création de 2 dépressions humides par étrépage (50 cm) - environ 2 x 200 m² | C7: TU 1 | D7: Réalisé
B8: Création d'un seuil en rondins de bois | C8: TU 2 | D8: Mesure supprimée (absence d’effet notable + conflit d’usage)
B9: Suppression et évacuation des ligneux | C9: TU 3 | D9: Réalisé
A10: Travaux de génie écologique (travaux d'entretien) | B10: Entretien des landes humides | C10: TE 1 | D10: Réalisé | H10: Projeté | K10: Projeté | N10: Projeté
D12: N+10 | E12: N+11 | F12: N+12 | G12: N+13 | H12: N+14 | I12: N+15 | J12: N+16 | K12: N+17 | L12: N+18 | M12: N+19 | N12: N+20
A13: TRAVAUX DE GENIE ECOLOGIQUE | C13: Code mesure | D13: 2034 | E13: 2035 | F13: 2036 | G13: 2037 | H13: 2038 | I13: 2039 | J13: 2040 | K13: 2041 | L13: 2042 | M13: 2043 | N13: 2044
A14: Travaux de génie écologique (travaux uniques) | B14: Pose de 1 piézomètres incluant la maintance tous les 5 ans et le remplacement au bout de 15 ans | C14: SE 1 | H14: Projeté | M14: Projeté
B15: Equipements des piézomètres avec des sondes et remplacement au bout de 10 ans | C15: SE 1 | M15: Projeté
B16: Installation et repli de chantier inlaunt la mise en place d'un grillage à mouton | C16: -
B17: Création de 2 dépressions humides par étrépage (50 cm) - environ 2 x 200 m² | C17: TU 1
B18: Création d'un seuil en rondins de bois | C18: TU 2
B19: Suppression et évacuation des ligneux | C19: TU 3
A20: Travaux de génie écologique (travaux d'entretien) | B20: Entretien des landes humides | C20: TE 1 | F20: Projeté | I20: Projeté | L20: Projeté
D22: N+21 | E22: N+22 | F22: N+23 | G22: N+24 | H22: N+25 | I22: N+26 | J22: N+27 | K22: N+28 | L22: N+29
A23: TRAVAUX DE GENIE ECOLOGIQUE | C23: Code mesure | D23: 2045 | E23: 2046 | F23: 2047 | G23: 2048 | H23: 2049 | I23: 2050 | J23: 2051 | K23: 2052 | L23: 2053
A24: Travaux de génie écologique (travaux uniques) | B24: Pose de 1 piézomètres incluant la maintance tous les 5 ans et le remplacement au bout de 15 ans | C24: SE 1 | G24: Projeté
B25: Equipements des piézomètres avec des sondes et remplacement au bout de 10 ans | C25: SE 1
B26: Installation et repli de chantier inlaunt la mise en place d'un grillage à mouton | C26: -
B27: Création de 2 dépressions humides par étrépage (50 cm) - environ 2 x 200 m² | C27: TU 1
B28: Création d'un seuil en rondins de bois | C28: TU 2
B29: Suppression et évacuation des ligneux | C29: TU 3
A30: Travaux de génie écologique (travaux d'entretien) | B30: Entretien des landes humides | C30: TE 1 | D30: Projeté | G30: Projeté | J30: Projeté
